<mujoco model="go1_x5">
  <compiler angle="radian" meshdir="assets" autolimits="true"/>

  <option cone="elliptic" impratio="100"/>

  <default>
    <!-- ================= GO1 DEFAULTS ================= -->
    <default class="go1">
      <geom friction="0.6" margin="0.001" condim="1"/>
      <joint axis="0 1 0" damping="0.2" armature="0.01" frictionloss="0.2"/>
      
      <default class="abduction">
        <joint axis="1 0 0"  range="-0.863 0.863"/>
        <position ctrlrange="-0.863 0.863"/>
      </default>
      <default class="hip">
        <joint range="-0.686 4.501"/>
        <position ctrlrange="-0.686 4.501"/>
      </default>
      <default class="knee">
        <joint range="-2.818 -0.888"/>
        <position forcerange="-35.55 35.55" ctrlrange="-2.818 -0.888"/>
      </default>
      
      <default class="go1_visual">
        <geom type="mesh" contype="0" conaffinity="0" group="2" material="dark"/>
      </default>
      <default class="go1_collision">
        <geom group="3" type="capsule"/>
        <default class="hip_left1">
          <geom size="0.046 0.02" pos="0 0.045 0" quat="1 1 0 0" type="cylinder"/>
        </default>
        <default class="hip_left2">
          <geom size="0.031 0.02" pos="0 0.065 0" quat="1 1 0 0" type="cylinder"/>
        </default>
        <default class="hip_left3">
          <geom size="0.046 0.02" quat="1 1 0 0" type="cylinder"/>
        </default>
        <default class="hip_right1">
          <geom size="0.046 0.02" pos="0 -0.045 0" quat="1 1 0 0" type="cylinder"/>
        </default>
        <default class="hip_right2">
          <geom size="0.031 0.02" pos="0 -0.065 0" quat="1 1 0 0" type="cylinder"/>
        </default>
        <default class="hip_right3">
          <geom size="0.046 0.02" quat="1 1 0 0" type="cylinder"/>
        </default>
        <default class="thigh1">
          <geom size="0.015" fromto="-0.02 0 0 -0.02 0 -0.16"/>
        </default>
        <default class="thigh2">
          <geom size="0.015" fromto="0 0 0 -0.02 0 -0.1"/>
        </default>
        <default class="thigh3">
          <geom size="0.015" fromto="-0.02 0 -0.16 0 0 -0.2"/>
        </default>
        <default class="calf1">
          <geom size="0.01" fromto="0 0 0 0.02 0 -0.13"/>
        </default>
        <default class="calf2">
          <geom size="0.01" fromto="0.02 0 -0.13 0 0 -0.2"/>
        </default>
        <default class="foot">
          <geom type="sphere" size="0.023" pos="0 0 -0.213" priority="1" solimp="0.015 1 0.023" condim="6" friction="0.8 0.02 0.01"/>
        </default>
      </default>
    </default>

    <!-- ARX5 Defaults -->
    <default class="arx5">
      <default class="arx5_motor">
        <joint />
        <motor />
      </default>
      <default class="arx5_visual">
        <geom material="default_material" contype="0" conaffinity="0" group="2" />
      </default>
    </default>
  </default>

  <asset>
    <!-- GO1 Assets -->
    <material name="dark" rgba="0.2 0.2 0.2 1"/>
    <mesh class="go1" file="trunk.stl"/>
    <mesh class="go1" file="hip.stl"/>
    <mesh class="go1" file="thigh_mirror.stl"/>
    <mesh class="go1" file="calf.stl"/>
    <mesh class="go1" file="thigh.stl"/>

    <!-- ARX5 Assets -->
    <material name="x5" rgba="1 1 1 1" />
    <material name="default_material" rgba="0.7 0.7 0.7 1" />
    <mesh name="x5_base_link" file="base_link.obj" />
    <mesh name="x5_link1" file="link1.obj" />
    <mesh name="x5_link2" file="link2.obj" />
    <mesh name="x5_link3" file="link3.obj" />
    <mesh name="x5_link4" file="link4.obj" />
    <mesh name="x5_link5" file="link5.obj" />
    <mesh name="x5_link6" file="link6.obj" />
    <mesh name="x5_link7" file="link7.obj" />
    <mesh name="x5_link8" file="link8.obj" />
  </asset>

  <worldbody>
    <light name="spotlight" mode="targetbodycom" target="trunk" pos="0 -1 2"/>
    
    <!-- ================= GO1 TRUNK ================= -->
    <body name="trunk" pos="0 0 0.445" childclass="go1">
      <camera name="tracking" mode="trackcom" pos="0 -1 0.8" xyaxes="1 0 0 0 1 1"/>
      <site name="head" pos="0.3 0 0" rgba="1 0 0 1" size="0.02" group="5"/>
      <inertial pos="0.0223 0.002 -0.0005" quat="-0.00342088 0.705204 0.000106698 0.708996" mass="5.204" diaginertia="0.0716565 0.0630105 0.0168101"/>
      <freejoint/>
      
      <geom class="go1_visual" mesh="trunk"/>
      <geom class="go1_collision" size="0.125 0.04 0.057" type="box"/>
      <geom class="go1_collision" quat="1 0 1 0" pos="0 -0.04 0" size="0.058 0.125" type="cylinder"/>
      <geom class="go1_collision" quat="1 0 1 0" pos="0 +0.04 0" size="0.058 0.125" type="cylinder"/>
      <geom class="go1_collision" pos="0.25 0 0" size="0.005 0.06 0.05" type="box"/>
      <geom class="go1_collision" pos="0.25 0.06 -0.01" size="0.009 0.035"/>
      <geom class="go1_collision" pos="0.25 -0.06 -0.01" size="0.009 0.035"/>
      <geom class="go1_collision" pos="0.25 0 -0.05" size="0.01 0.06" quat="1 1 0 0"/>
      <geom class="go1_collision" pos="0.255 0 0.0355" size="0.021 0.052" quat="1 1 0 0"/>
      <site name="imu" pos="0 0 0"/>

      <!-- GO1 LEGS -->
      <body name="FL_hip" pos="0.1881 0.04675 0">
        <inertial pos="-0.0049166 -0.00762615 -8.865e-05" quat="0.482891 0.495027 0.514169 0.507341" mass="0.68" diaginertia="0.000734064 0.000468438 0.000398719"/>
        <joint class="abduction" name="FL_hip_joint"/>
        <geom class="go1_visual" mesh="hip"/>
        <geom class="hip_left1"/>
        <geom class="hip_left2"/>
        <body name="FL_thigh" pos="0 0.08 0">
          <inertial pos="-0.00304722 -0.019315 -0.0305004" quat="0.753383 0.0775126 -0.0272313 0.65243" mass="1.009" diaginertia="0.00478717 0.00460903 0.000709268"/>
          <joint class="hip" name="FL_thigh_joint"/>
          <geom class="go1_visual" mesh="thigh"/>
          <geom class="thigh1"/>
          <geom class="thigh2"/>
          <geom class="thigh3"/>
          <body name="FL_calf" pos="0 0 -0.213">
            <inertial pos="0.00429862 0.000976676 -0.146197" quat="0.691246 0.00357467 0.00511118 0.722592" mass="0.195862" diaginertia="0.00149767 0.00148468 3.58427e-05"/>
            <joint class="knee" name="FL_calf_joint"/>
            <geom class="go1_visual" mesh="calf"/>
            <geom class="calf1"/>
            <geom class="calf2"/>
            <geom name="FL" class="foot"/>
            <site name="FL" pos="0 0 -0.213" type="sphere" size="0.023" group="5"/>
          </body>
        </body>
      </body>

      <body name="FR_hip" pos="0.1881 -0.04675 0">
        <inertial pos="-0.0049166 0.00762615 -8.865e-05" quat="0.507341 0.514169 0.495027 0.482891" mass="0.68" diaginertia="0.000734064 0.000468438 0.000398719"/>
        <joint class="abduction" name="FR_hip_joint"/>
        <geom class="go1_visual" mesh="hip" quat="1 0 0 0"/>
        <geom class="hip_right1"/>
        <geom class="hip_right2"/>
        <body name="FR_thigh" pos="0 -0.08 0">
          <inertial pos="-0.00304722 0.019315 -0.0305004" quat="0.65243 -0.0272313 0.0775126 0.753383" mass="1.009" diaginertia="0.00478717 0.00460903 0.000709268"/>
          <joint class="hip" name="FR_thigh_joint"/>
          <geom class="go1_visual" mesh="thigh_mirror"/>
          <geom class="thigh1"/>
          <geom class="thigh2"/>
          <geom class="thigh3"/>
          <body name="FR_calf" pos="0 0 -0.213">
            <inertial pos="0.00429862 0.000976676 -0.146197" quat="0.691246 0.00357467 0.00511118 0.722592" mass="0.195862" diaginertia="0.00149767 0.00148468 3.58427e-05"/>
            <joint class="knee" name="FR_calf_joint"/>
            <geom class="go1_visual" mesh="calf"/>
            <geom class="calf1"/>
            <geom class="calf2"/>
            <geom name="FR" class="foot"/>
            <site name="FR" pos="0 0 -0.213" type="sphere" size="0.023" group="5"/>
          </body>
        </body>
      </body>

      <body name="RL_hip" pos="-0.1881 0.04675 0">
        <inertial pos="0.0049166 -0.00762615 -8.865e-05" quat="0.514169 0.507341 0.482891 0.495027" mass="0.68" diaginertia="0.000734064 0.000468438 0.000398719"/>
        <joint class="abduction" name="RL_hip_joint"/>
        <geom class="go1_visual" quat="0 0 1 0" mesh="hip"/>
        <geom class="hip_left1"/>
        <geom class="hip_left2"/>
        <geom class="hip_left3"/>
        <body name="RL_thigh" pos="0 0.08 0">
          <inertial pos="-0.00304722 -0.019315 -0.0305004" quat="0.753383 0.0775126 -0.0272313 0.65243" mass="1.009" diaginertia="0.00478717 0.00460903 0.000709268"/>
          <joint class="hip" name="RL_thigh_joint"/>
          <geom class="go1_visual" mesh="thigh"/>
          <geom class="thigh1"/>
          <geom class="thigh2"/>
          <geom class="thigh3"/>
          <body name="RL_calf" pos="0 0 -0.213">
            <inertial pos="0.00429862 0.000976676 -0.146197" quat="0.691246 0.00357467 0.00511118 0.722592" mass="0.195862" diaginertia="0.00149767 0.00148468 3.58427e-05"/>
            <joint class="knee" name="RL_calf_joint"/>
            <geom class="go1_visual" mesh="calf"/>
            <geom class="calf1"/>
            <geom class="calf2"/>
            <geom name="RL" class="foot"/>
            <site name="RL" pos="0 0 -0.213" type="sphere" size="0.023" group="5"/>
          </body>
        </body>
      </body>

      <body name="RR_hip" pos="-0.1881 -0.04675 0">
        <inertial pos="0.0049166 0.00762615 -8.865e-05" quat="0.495027 0.482891 0.507341 0.514169" mass="0.68" diaginertia="0.000734064 0.000468438 0.000398719"/>
        <joint class="abduction" name="RR_hip_joint"/>
        <geom class="go1_visual" quat="0 0 0 -1" mesh="hip"/>
        <geom class="hip_right1"/>
        <geom class="hip_right2"/>
        <geom class="hip_right3"/>
        <body name="RR_thigh" pos="0 -0.08 0">
          <inertial pos="-0.00304722 0.019315 -0.0305004" quat="0.65243 -0.0272313 0.0775126 0.753383" mass="1.009" diaginertia="0.00478717 0.00460903 0.000709268"/>
          <joint class="hip" name="RR_thigh_joint"/>
          <geom class="go1_visual" mesh="thigh_mirror"/>
          <geom class="thigh1"/>
          <geom class="thigh2"/>
          <geom class="thigh3"/>
          <body name="RR_calf" pos="0 0 -0.213">
            <inertial pos="0.00429862 0.000976676 -0.146197" quat="0.691246 0.00357467 0.00511118 0.722592" mass="0.195862" diaginertia="0.00149767 0.00148468 3.58427e-05"/>
            <joint class="knee" name="RR_calf_joint"/>
            <geom class="go1_visual" mesh="calf"/>
            <geom class="calf1"/>
            <geom class="calf2"/>
            <geom name="RR" class="foot"/>
            <site name="RR" pos="0 0 -0.213" type="sphere" size="0.023" group="5"/>
          </body>
        </body>
      </body>
      

      <!-- ================= ARX5 Robotic Arm Mount ================= -->
      <body name="x5_base_link" pos="0.0 0 0.06" quat="1 0 0 0" childclass="arx5">
        <geom name="x5_base_link_visual" pos="0 0 0" quat="1.0 0.0 0.0 0.0" type="mesh" mesh="x5_base_link" class="arx5_visual" />
        
        <body name="x5_link1" pos="0 0 0.0605" quat="1.0 0.0 0.0 0.0">
          <joint name="x5_joint1" type="hinge" ref="0.0" class="arx5_motor" range="-3 3" damping="1" axis="0 0 1" />
          <inertial pos="0.0054231 -0.0080289 0.017086" quat="1.0 0.0 0.0 0.0" mass="0.066982" diaginertia="8e-05 3e-05 8e-05" />
          <geom name="x5_link1_visual" pos="0 0 0" quat="1.0 0.0 0.0 0.0" type="mesh" mesh="x5_link1" class="arx5_visual" />
          
          <body name="x5_link2" pos="0.02 0 0.04" quat="1.0 0.0 0.0 0.0">
            <joint name="x5_joint2" type="hinge" ref="0.0" class="arx5_motor" range="-0 3" damping="1" axis="0 1 0" />
            <inertial pos="-0.13237 0.0020852 0.00010549" quat="1.0 0.0 0.0 0.0" mass="1.0795" diaginertia="0.00051 0.01599 0.01605" />
            <geom name="x5_link2_visual" pos="0 0 0" quat="1.0 0.0 0.0 0.0" type="mesh" mesh="x5_link2" class="arx5_visual" />
            
            <body name="x5_link3" pos="-0.264 0 0" quat="-3.673205103346574e-06 0.9999999999932537 0.0 -0.0">
              <joint name="x5_joint3" type="hinge" ref="0.0" class="arx5_motor" range="-0 3"  damping="1" axis="0 1 0" />
              <inertial pos="0.18531 0.00068376 -0.051638" quat="1.0 0.0 0.0 0.0" mass="0.54534" diaginertia="0.00036 0.00423 0.0042" />
              <geom name="x5_link3_visual" pos="0 0 0" quat="1.0 0.0 0.0 0.0" type="mesh" mesh="x5_link3" class="arx5_visual" />
              
              <body name="x5_link4" pos="0.245 0 -0.056" quat="1.0 0.0 0.0 0.0">
                <joint name="x5_joint4" type="hinge" ref="0.0" class="arx5_motor" range="-1.5 1.5" damping="1" axis="0 1 0" />
                <inertial pos="0.040231 0.0044807 -0.035335" quat="1.0 0.0 0.0 0.0" mass="0.11714" diaginertia="0.00019 0.00023 0.00014" />
                <geom name="x5_link4_visual" pos="0 0 0" quat="1.0 0.0 0.0 0.0" type="mesh" mesh="x5_link4" class="arx5_visual" />
                
                <body name="x5_link5" pos="0.06775 0.0005 -0.0865" quat="1.0 0.0 0.0 0.0">
                  <joint name="x5_joint5" type="hinge" ref="0.0" class="arx5_motor" range="-1.5 1.5" damping="1" axis="0 0 1" />
                  <inertial pos="0.003612 -1.5455E-05 0.055214" quat="1.0 0.0 0.0 0.0" mass="0.63488" diaginertia="0.00083 0.00082 0.00026" />
                  <geom name="x5_link5_visual" pos="0 0 0" quat="1.0 0.0 0.0 0.0" type="mesh" mesh="x5_link5" class="arx5_visual" />
                  
                  <body name="x5_link6" pos="0.02895 0 0.0865" quat="-3.673205103346574e-06 -0.9999999999932537 -0.0 0.0">
                    <joint name="x5_joint6" type="hinge" ref="0.0" class="arx5_motor" range="-3 3" damping="1" axis="1 0 0" />
                    <inertial pos="0.041697 2.4368E-05 0.00014464" quat="1.0 0.0 0.0 0.0" mass="0.44089" diaginertia="0.00038 0.00028 0.0005" />
                    <geom name="x5_link6_visual" pos="0 0 0" quat="1.0 0.0 0.0 0.0" type="mesh" mesh="x5_link6" class="arx5_visual" />
                    
                    <body name="x5_link7" pos="0.08657 0.024896 -0.0002436" quat="1.0 0.0 0.0 0.0">
                      <inertial pos="-0.00035522 -0.007827 -0.0029883" quat="1.0 0.0 0.0 0.0" mass="0.064798" diaginertia="2e-05 3e-05 3e-05" />
                      <geom name="x5_link7_visual" pos="0 0 0" quat="1.0 0.0 0.0 0.0" type="mesh" mesh="x5_link7" class="arx5_visual" />
                    </body>
                    
                    <body name="x5_link8" pos="0.08657 -0.0249 -0.00024366" quat="1.0 0.0 0.0 0.0">
                      <inertial pos="-0.00035522 0.0078277 0.0024201" quat="1.0 0.0 0.0 0.0" mass="0.064798" diaginertia="2e-05 3e-05 3e-05" />
                      <geom name="x5_link8_visual" pos="0 0 0" quat="1.0 0.0 0.0 0.0" type="mesh" mesh="x5_link8" class="arx5_visual" />
                    </body>
                  </body>
                </body>
              </body>
            </body>
          </body>
        </body>
        
        <site name="x5_base_link_site" pos="0 0 0" quat="1 0 0 0" />
        <camera name="x5_front_camera" mode="track" fovy="90.0" quat="0 0 0.70710678 0.70710678" pos="0.0 2.0 0.5" />
        <camera name="x5_side_camera" mode="track" fovy="90.0" quat="-0.5 -0.5 0.5 0.5" pos="-2.0 0.0 0.5" />
      </body>

    </body>
  </worldbody>
  <contact>
    <exclude body1="x5_base_link" body2="x5_link1" />
    <exclude body1="x5_link1" body2="x5_link2" />
    <exclude body1="x5_link2" body2="x5_link3" />
    <exclude body1="x5_link3" body2="x5_link4" />
    <exclude body1="x5_link4" body2="x5_link5" />
    <exclude body1="x5_link5" body2="x5_link6" />
    <exclude body1="x5_link6" body2="x5_link7" />
    <exclude body1="x5_link6" body2="x5_link8" />
  </contact>

  <actuator>
    <!-- GO1 Actuators -->
    <motor class="abduction" name="FL_hip" joint="FL_hip_joint" ctrlrange="-23.7 23.7"/>
    <motor class="hip" name="FL_thigh" joint="FL_thigh_joint" ctrlrange="-23.7 23.7"/>
    <motor class="knee" name="FL_calf" joint="FL_calf_joint" ctrlrange="-45.43 45.43"/>

    <motor class="abduction" name="FR_hip" joint="FR_hip_joint" ctrlrange="-23.7 23.7"/>
    <motor class="hip" name="FR_thigh" joint="FR_thigh_joint" ctrlrange="-23.7 23.7"/>
    <motor class="knee" name="FR_calf" joint="FR_calf_joint" ctrlrange="-45.43 45.43"/>

    <motor class="abduction" name="RL_hip" joint="RL_hip_joint" ctrlrange="-23.7 23.7"/>
    <motor class="hip" name="RL_thigh" joint="RL_thigh_joint" ctrlrange="-23.7 23.7"/>
    <motor class="knee" name="RL_calf" joint="RL_calf_joint" ctrlrange="-45.43 45.43"/>

    <motor class="abduction" name="RR_hip" joint="RR_hip_joint" ctrlrange="-23.7 23.7"/>
    <motor class="hip" name="RR_thigh" joint="RR_thigh_joint" ctrlrange="-23.7 23.7"/>
    <motor class="knee" name="RR_calf" joint="RR_calf_joint" ctrlrange="-45.43 45.43"/>


    <!-- ARX5 Actuators -->
    <motor name="x5_joint1_ctrl" joint="x5_joint1" class="arx5_motor" ctrlrange="-20.0 20.0"/>
    <motor name="x5_joint2_ctrl" joint="x5_joint2" class="arx5_motor" ctrlrange="-20.0 20.0"/>
    <motor name="x5_joint3_ctrl" joint="x5_joint3" class="arx5_motor" ctrlrange="-20.0 20.0"/>
    <motor name="x5_joint4_ctrl" joint="x5_joint4" class="arx5_motor" ctrlrange="-7.0 7.0"/>
    <motor name="x5_joint5_ctrl" joint="x5_joint5" class="arx5_motor" ctrlrange="-5.0 5.0"/>
    <motor name="x5_joint6_ctrl" joint="x5_joint6" class="arx5_motor" ctrlrange="-5.0 5.0"/>

  </actuator>


</mujoco>