<mujoco model="go2_arx5">
  <compiler angle="radian" meshdir="assets" autolimits="true"/>

  <option cone="elliptic" impratio="100"/>

  <default>
    <!-- Go2 Defaults -->
    <default class="go2">
      <geom friction="0.4" margin="0.001" condim="1"/>
      <joint axis="0 1 0" damping="0.1" armature="0.01" frictionloss="0.2"/>
      <motor ctrlrange="-23.7 23.7"/>
      <default class="abduction">
        <joint axis="1 0 0" range="-1.0472 1.0472"/>
        <motor ctrlrange="-23.7 23.7"/>
      </default>
      <default class="hip">
        <default class="front_hip">
          <joint range="-1.5708 3.4907"/>
          <motor ctrlrange="-23.7 23.7"/>
        </default>
        <default class="back_hip">
          <joint range="-0.5236 4.5379"/>
          <motor ctrlrange="-23.7 23.7"/>
        </default>
      </default>
      <default class="knee">
        <joint range="-2.7227 -0.83776"/>
        <motor ctrlrange="-35.5 35.5"/>
      </default>
      <default class="visual">
        <geom type="mesh" contype="0" conaffinity="0" group="2"/>
      </default>
      <default class="collision">
        <geom group="3"/>
        <default class="foot">
          <geom size="0.022" pos="-0.002 0 -0.213" priority="1" condim="6"
            friction="0.8 0.02 0.01"/>
        </default>
      </default>
    </default>

    <!-- ARX5 Defaults -->
    <default class="arx5">
      <default class="arx5_motor">
        <joint />
        <motor />
      </default>
      <default class="arx5_visual">
        <geom material="default_material" contype="0" conaffinity="0" group="2" />
      </default>
    </default>
  </default>

  <asset>
    <!-- Go2 Assets -->
    <material name="metal" rgba=".9 .95 .95 1"/>
    <material name="black" rgba="0 0 0 1"/>
    <material name="white" rgba="1 1 1 1"/>
    <material name="gray" rgba="0.671705 0.692426 0.774270 1"/>

    <mesh file="base_0.obj"/>
    <mesh file="base_1.obj"/>
    <mesh file="base_2.obj"/>
    <mesh file="base_3.obj"/>
    <mesh file="base_4.obj"/>
    <mesh file="hip_0.obj"/>
    <mesh file="hip_1.obj"/>
    <mesh file="thigh_0.obj"/>
    <mesh file="thigh_1.obj"/>
    <mesh file="thigh_mirror_0.obj"/>
    <mesh file="thigh_mirror_1.obj"/>
    <mesh file="calf_0.obj"/>
    <mesh file="calf_1.obj"/>
    <mesh file="calf_mirror_0.obj"/>
    <mesh file="calf_mirror_1.obj"/>
    <mesh file="foot.obj"/>

    <!-- ARX5 Assets -->
    <material name="x5" rgba="1 1 1 1" />
    <material name="default_material" rgba="0.7 0.7 0.7 1" />
    <mesh name="x5_base_link" file="base_link.obj" />
    <mesh name="x5_link1" file="link1.obj" />
    <mesh name="x5_link2" file="link2.obj" />
    <mesh name="x5_link3" file="link3.obj" />
    <mesh name="x5_link4" file="link4.obj" />
    <mesh name="x5_link5" file="link5.obj" />
    <mesh name="x5_link6" file="link6.obj" />
    <mesh name="x5_link7" file="link7.obj" />
    <mesh name="x5_link8" file="link8.obj" />
  </asset>

  <worldbody>
    <body name="base" pos="0 0 0.445" childclass="go2">
      <inertial pos="0.021112 0 -0.005366" quat="-0.000543471 0.713435 -0.00173769 0.700719" mass="6.921"
        diaginertia="0.107027 0.0980771 0.0244531"/>
      <freejoint/>
      
      <!-- Go2 Base Geometry -->
      <geom mesh="base_0" material="black" class="visual"/>
      <geom mesh="base_1" material="black" class="visual"/>
      <geom mesh="base_2" material="black" class="visual"/>
      <geom mesh="base_3" material="white" class="visual"/>
      <geom mesh="base_4" material="gray" class="visual"/>
      <geom size="0.1881 0.04675 0.057" type="box" class="collision"/>
      <geom size="0.05 0.045" pos="0.285 0 0.01" type="cylinder" class="collision"/>
      <geom size="0.047" pos="0.293 0 -0.06" class="collision"/>
      <site name="imu" pos="-0.02557 0 0.04232"/>

      <!-- ================= End of ARX5 Arm ================= -->

      <!-- Go2 Legs -->
      <body name="FL_hip" pos="0.1934 0.0465 0">
        <inertial pos="-0.0054 0.00194 -0.000105" quat="0.497014 0.499245 0.505462 0.498237" mass="0.678"
          diaginertia="0.00088403 0.000596003 0.000479967"/>
        <joint name="FL_hip_joint" class="abduction"/>
        <geom mesh="hip_0" material="metal" class="visual"/>
        <geom mesh="hip_1" material="gray" class="visual"/>
        <geom size="0.046 0.02" pos="0 0.08 0" quat="1 1 0 0" type="cylinder" class="collision"/>
        <body name="FL_thigh" pos="0 0.0955 0">
          <inertial pos="-0.00374 -0.0223 -0.0327" quat="0.829533 0.0847635 -0.0200632 0.551623" mass="1.152"
            diaginertia="0.00594973 0.00584149 0.000878787"/>
          <joint name="FL_thigh_joint" class="front_hip"/>
          <geom mesh="thigh_0" material="metal" class="visual"/>
          <geom mesh="thigh_1" material="gray" class="visual"/>
          <geom size="0.1065 0.01225 0.017" pos="0 0 -0.1065" quat="0.707107 0 0.707107 0" type="box" class="collision"/>
          <body name="FL_calf" pos="0 0 -0.213">
            <inertial pos="0.00629595 -0.000622121 -0.141417" quat="0.710672 0.00154099 -0.00450087 0.703508"
              mass="0.241352" diaginertia="0.0014901 0.00146356 5.31397e-05"/>
            <joint name="FL_calf_joint" class="knee"/>
            <geom mesh="calf_0" material="gray" class="visual"/>
            <geom mesh="calf_1" material="black" class="visual"/>
            <geom size="0.012 0.06" pos="0.008 0 -0.06" quat="0.994493 0 -0.104807 0" type="cylinder" class="collision"/>
            <geom size="0.011 0.0325" pos="0.02 0 -0.148" quat="0.999688 0 0.0249974 0" type="cylinder" class="collision"/>
            <geom pos="0 0 -0.213" mesh="foot" class="visual" material="black"/>
            <geom name="FL" class="foot"/>
          </body>
        </body>
      </body>
      <body name="FR_hip" pos="0.1934 -0.0465 0">
        <inertial pos="-0.0054 -0.00194 -0.000105" quat="0.498237 0.505462 0.499245 0.497014" mass="0.678"
          diaginertia="0.00088403 0.000596003 0.000479967"/>
        <joint name="FR_hip_joint" class="abduction"/>
        <geom mesh="hip_0" material="metal" class="visual" quat="4.63268e-05 1 0 0"/>
        <geom mesh="hip_1" material="gray" class="visual" quat="4.63268e-05 1 0 0"/>
        <geom size="0.046 0.02" pos="0 -0.08 0" quat="0.707107 0.707107 0 0" type="cylinder" class="collision"/>
        <body name="FR_thigh" pos="0 -0.0955 0">
          <inertial pos="-0.00374 0.0223 -0.0327" quat="0.551623 -0.0200632 0.0847635 0.829533" mass="1.152"
            diaginertia="0.00594973 0.00584149 0.000878787"/>
          <joint name="FR_thigh_joint" class="front_hip"/>
          <geom mesh="thigh_mirror_0" material="metal" class="visual"/>
          <geom mesh="thigh_mirror_1" material="gray" class="visual"/>
          <geom size="0.1065 0.01225 0.017" pos="0 0 -0.1065" quat="0.707107 0 0.707107 0" type="box" class="collision"/>
          <body name="FR_calf" pos="0 0 -0.213">
            <inertial pos="0.00629595 0.000622121 -0.141417" quat="0.703508 -0.00450087 0.00154099 0.710672"
              mass="0.241352" diaginertia="0.0014901 0.00146356 5.31397e-05"/>
            <joint name="FR_calf_joint" class="knee"/>
            <geom mesh="calf_mirror_0" material="gray" class="visual"/>
            <geom mesh="calf_mirror_1" material="black" class="visual"/>
            <geom size="0.013 0.06" pos="0.01 0 -0.06" quat="0.995004 0 -0.0998334 0" type="cylinder" class="collision"/>
            <geom size="0.011 0.0325" pos="0.02 0 -0.148" quat="0.999688 0 0.0249974 0" type="cylinder" class="collision"/>
            <geom pos="0 0 -0.213" mesh="foot" class="visual" material="black"/>
            <geom name="FR" class="foot"/>
          </body>
        </body>
      </body>
      <body name="RL_hip" pos="-0.1934 0.0465 0">
        <inertial pos="0.0054 0.00194 -0.000105" quat="0.505462 0.498237 0.497014 0.499245" mass="0.678"
          diaginertia="0.00088403 0.000596003 0.000479967"/>
        <joint name="RL_hip_joint" class="abduction"/>
        <geom mesh="hip_0" material="metal" class="visual" quat="4.63268e-05 0 1 0"/>
        <geom mesh="hip_1" material="gray" class="visual" quat="4.63268e-05 0 1 0"/>
        <geom size="0.046 0.02" pos="0 0.08 0" quat="0.707107 0.707107 0 0" type="cylinder" class="collision"/>
        <body name="RL_thigh" pos="0 0.0955 0">
          <inertial pos="-0.00374 -0.0223 -0.0327" quat="0.829533 0.0847635 -0.0200632 0.551623" mass="1.152"
            diaginertia="0.00594973 0.00584149 0.000878787"/>
          <joint name="RL_thigh_joint" class="back_hip"/>
          <geom mesh="thigh_0" material="metal" class="visual"/>
          <geom mesh="thigh_1" material="gray" class="visual"/>
          <geom size="0.1065 0.01225 0.017" pos="0 0 -0.1065" quat="0.707107 0 0.707107 0" type="box" class="collision"/>
          <body name="RL_calf" pos="0 0 -0.213">
            <inertial pos="0.00629595 -0.000622121 -0.141417" quat="0.710672 0.00154099 -0.00450087 0.703508"
              mass="0.241352" diaginertia="0.0014901 0.00146356 5.31397e-05"/>
            <joint name="RL_calf_joint" class="knee"/>
            <geom mesh="calf_0" material="gray" class="visual"/>
            <geom mesh="calf_1" material="black" class="visual"/>
            <geom size="0.013 0.06" pos="0.01 0 -0.06" quat="0.995004 0 -0.0998334 0" type="cylinder" class="collision"/>
            <geom size="0.011 0.0325" pos="0.02 0 -0.148" quat="0.999688 0 0.0249974 0" type="cylinder" class="collision"/>
            <geom pos="0 0 -0.213" mesh="foot" class="visual" material="black"/>
            <geom name="RL" class="foot"/>
          </body>
        </body>
      </body>
      <body name="RR_hip" pos="-0.1934 -0.0465 0">
        <inertial pos="0.0054 -0.00194 -0.000105" quat="0.499245 0.497014 0.498237 0.505462" mass="0.678"
          diaginertia="0.00088403 0.000596003 0.000479967"/>
        <joint name="RR_hip_joint" class="abduction"/>
        <geom mesh="hip_0" material="metal" class="visual" quat="2.14617e-09 4.63268e-05 4.63268e-05 -1"/>
        <geom mesh="hip_1" material="gray" class="visual" quat="2.14617e-09 4.63268e-05 4.63268e-05 -1"/>
        <geom size="0.046 0.02" pos="0 -0.08 0" quat="0.707107 0.707107 0 0" type="cylinder" class="collision"/>
        <body name="RR_thigh" pos="0 -0.0955 0">
          <inertial pos="-0.00374 0.0223 -0.0327" quat="0.551623 -0.0200632 0.0847635 0.829533" mass="1.152"
            diaginertia="0.00594973 0.00584149 0.000878787"/>
          <joint name="RR_thigh_joint" class="back_hip"/>
          <geom mesh="thigh_mirror_0" material="metal" class="visual"/>
          <geom mesh="thigh_mirror_1" material="gray" class="visual"/>
          <geom size="0.1065 0.01225 0.017" pos="0 0 -0.1065" quat="0.707107 0 0.707107 0" type="box" class="collision"/>
          <body name="RR_calf" pos="0 0 -0.213">
            <inertial pos="0.00629595 0.000622121 -0.141417" quat="0.703508 -0.00450087 0.00154099 0.710672"
              mass="0.241352" diaginertia="0.0014901 0.00146356 5.31397e-05"/>
            <joint name="RR_calf_joint" class="knee"/>
            <geom mesh="calf_mirror_0" material="gray" class="visual"/>
            <geom mesh="calf_mirror_1" material="black" class="visual"/>
            <geom size="0.013 0.06" pos="0.01 0 -0.06" quat="0.995004 0 -0.0998334 0" type="cylinder" class="collision"/>
            <geom size="0.011 0.0325" pos="0.02 0 -0.148" quat="0.999688 0 0.0249974 0" type="cylinder" class="collision"/>
            <geom pos="0 0 -0.213" mesh="foot" class="visual" material="black"/>
            <geom name="RR" class="foot"/>
          </body>
        </body>
      </body>


      <!-- ================= ARX5 Robotic Arm Mount ================= -->
      <body name="x5_base_link" pos="0.0 0 0.06" quat="1 0 0 0" childclass="arx5">
        <geom name="x5_base_link_visual" pos="0 0 0" quat="1.0 0.0 0.0 0.0" type="mesh" mesh="x5_base_link" class="arx5_visual" />
        
        <body name="x5_link1" pos="0 0 0.0605" quat="1.0 0.0 0.0 0.0">
          <joint name="x5_joint1" type="hinge" ref="0.0" class="arx5_motor" range="-3 3" damping="1" axis="0 0 1" />
          <inertial pos="0.0054231 -0.0080289 0.017086" quat="1.0 0.0 0.0 0.0" mass="0.066982" diaginertia="8e-05 3e-05 8e-05" />
          <geom name="x5_link1_visual" pos="0 0 0" quat="1.0 0.0 0.0 0.0" type="mesh" mesh="x5_link1" class="arx5_visual" />
          
          <body name="x5_link2" pos="0.02 0 0.04" quat="1.0 0.0 0.0 0.0">
            <joint name="x5_joint2" type="hinge" ref="0.0" class="arx5_motor" range="-0 3" damping="1" axis="0 1 0" />
            <inertial pos="-0.13237 0.0020852 0.00010549" quat="1.0 0.0 0.0 0.0" mass="1.0795" diaginertia="0.00051 0.01599 0.01605" />
            <geom name="x5_link2_visual" pos="0 0 0" quat="1.0 0.0 0.0 0.0" type="mesh" mesh="x5_link2" class="arx5_visual" />
            
            <body name="x5_link3" pos="-0.264 0 0" quat="-3.673205103346574e-06 0.9999999999932537 0.0 -0.0">
              <joint name="x5_joint3" type="hinge" ref="0.0" class="arx5_motor" range="-0 3"  damping="1" axis="0 1 0" />
              <inertial pos="0.18531 0.00068376 -0.051638" quat="1.0 0.0 0.0 0.0" mass="0.54534" diaginertia="0.00036 0.00423 0.0042" />
              <geom name="x5_link3_visual" pos="0 0 0" quat="1.0 0.0 0.0 0.0" type="mesh" mesh="x5_link3" class="arx5_visual" />
              
              <body name="x5_link4" pos="0.245 0 -0.056" quat="1.0 0.0 0.0 0.0">
                <joint name="x5_joint4" type="hinge" ref="0.0" class="arx5_motor" range="-1.5 1.5" damping="1" axis="0 1 0" />
                <inertial pos="0.040231 0.0044807 -0.035335" quat="1.0 0.0 0.0 0.0" mass="0.11714" diaginertia="0.00019 0.00023 0.00014" />
                <geom name="x5_link4_visual" pos="0 0 0" quat="1.0 0.0 0.0 0.0" type="mesh" mesh="x5_link4" class="arx5_visual" />
                
                <body name="x5_link5" pos="0.06775 0.0005 -0.0865" quat="1.0 0.0 0.0 0.0">
                  <joint name="x5_joint5" type="hinge" ref="0.0" class="arx5_motor" range="-1.5 1.5" damping="1" axis="0 0 1" />
                  <inertial pos="0.003612 -1.5455E-05 0.055214" quat="1.0 0.0 0.0 0.0" mass="0.63488" diaginertia="0.00083 0.00082 0.00026" />
                  <geom name="x5_link5_visual" pos="0 0 0" quat="1.0 0.0 0.0 0.0" type="mesh" mesh="x5_link5" class="arx5_visual" />
                  
                  <body name="x5_link6" pos="0.02895 0 0.0865" quat="-3.673205103346574e-06 -0.9999999999932537 -0.0 0.0">
                    <joint name="x5_joint6" type="hinge" ref="0.0" class="arx5_motor" range="-3 3" damping="1" axis="1 0 0" />
                    <inertial pos="0.041697 2.4368E-05 0.00014464" quat="1.0 0.0 0.0 0.0" mass="0.44089" diaginertia="0.00038 0.00028 0.0005" />
                    <geom name="x5_link6_visual" pos="0 0 0" quat="1.0 0.0 0.0 0.0" type="mesh" mesh="x5_link6" class="arx5_visual" />
                    
                    <body name="x5_link7" pos="0.08657 0.024896 -0.0002436" quat="1.0 0.0 0.0 0.0">
                      <inertial pos="-0.00035522 -0.007827 -0.0029883" quat="1.0 0.0 0.0 0.0" mass="0.064798" diaginertia="2e-05 3e-05 3e-05" />
                      <geom name="x5_link7_visual" pos="0 0 0" quat="1.0 0.0 0.0 0.0" type="mesh" mesh="x5_link7" class="arx5_visual" />
                    </body>
                    
                    <body name="x5_link8" pos="0.08657 -0.0249 -0.00024366" quat="1.0 0.0 0.0 0.0">
                      <inertial pos="-0.00035522 0.0078277 0.0024201" quat="1.0 0.0 0.0 0.0" mass="0.064798" diaginertia="2e-05 3e-05 3e-05" />
                      <geom name="x5_link8_visual" pos="0 0 0" quat="1.0 0.0 0.0 0.0" type="mesh" mesh="x5_link8" class="arx5_visual" />
                    </body>
                  </body>
                </body>
              </body>
            </body>
          </body>
        </body>
        
        <site name="x5_base_link_site" pos="0 0 0" quat="1 0 0 0" />
        <camera name="x5_front_camera" mode="track" fovy="90.0" quat="0 0 0.70710678 0.70710678" pos="0.0 2.0 0.5" />
        <camera name="x5_side_camera" mode="track" fovy="90.0" quat="-0.5 -0.5 0.5 0.5" pos="-2.0 0.0 0.5" />
      </body>
    
    </body>
  </worldbody>

  <contact>
    <exclude body1="x5_base_link" body2="x5_link1" />
    <exclude body1="x5_link1" body2="x5_link2" />
    <exclude body1="x5_link2" body2="x5_link3" />
    <exclude body1="x5_link3" body2="x5_link4" />
    <exclude body1="x5_link4" body2="x5_link5" />
    <exclude body1="x5_link5" body2="x5_link6" />
    <exclude body1="x5_link6" body2="x5_link7" />
    <exclude body1="x5_link6" body2="x5_link8" />
  </contact>

  <sensor>
    <!-- ARX5 Sensors with renamed targets -->
    <framepos name="x5_base_link_site_pos" objtype="site" objname="x5_base_link_site" />
    <framequat name="x5_base_link_site_quat" objtype="site" objname="x5_base_link_site" />
    <framelinvel name="x5_base_link_site_linvel" objtype="site" objname="x5_base_link_site" />
    <frameangvel name="x5_base_link_site_angvel" objtype="site" objname="x5_base_link_site" />
    <velocimeter name="x5_base_link_site_vel" site="x5_base_link_site" />
  </sensor>

  <actuator>
    <!-- Go2 Actuators -->
    <motor class="abduction" name="FL_hip" joint="FL_hip_joint" ctrlrange="-23.7 23.7"/>
    <motor class="hip" name="FL_thigh" joint="FL_thigh_joint" ctrlrange="-23.7 23.7"/>
    <motor class="knee" name="FL_calf" joint="FL_calf_joint" ctrlrange="-45.43 45.43"/>

    <motor class="abduction" name="FR_hip" joint="FR_hip_joint" ctrlrange="-23.7 23.7"/>
    <motor class="hip" name="FR_thigh" joint="FR_thigh_joint" ctrlrange="-23.7 23.7"/>
    <motor class="knee" name="FR_calf" joint="FR_calf_joint" ctrlrange="-45.43 45.43"/>

    <motor class="abduction" name="RL_hip" joint="RL_hip_joint" ctrlrange="-23.7 23.7"/>
    <motor class="hip" name="RL_thigh" joint="RL_thigh_joint" ctrlrange="-23.7 23.7"/>
    <motor class="knee" name="RL_calf" joint="RL_calf_joint" ctrlrange="-45.43 45.43"/>

    <motor class="abduction" name="RR_hip" joint="RR_hip_joint" ctrlrange="-23.7 23.7"/>
    <motor class="hip" name="RR_thigh" joint="RR_thigh_joint" ctrlrange="-23.7 23.7"/>
    <motor class="knee" name="RR_calf" joint="RR_calf_joint" ctrlrange="-45.43 45.43"/>

    
    <!-- ARX5 Actuators -->
    <motor name="x5_joint1_ctrl" joint="x5_joint1" class="arx5_motor" ctrlrange="-20.0 20.0"/>
    <motor name="x5_joint2_ctrl" joint="x5_joint2" class="arx5_motor" ctrlrange="-20.0 20.0"/>
    <motor name="x5_joint3_ctrl" joint="x5_joint3" class="arx5_motor" ctrlrange="-20.0 20.0"/>
    <motor name="x5_joint4_ctrl" joint="x5_joint4" class="arx5_motor" ctrlrange="-7.0 7.0"/>
    <motor name="x5_joint5_ctrl" joint="x5_joint5" class="arx5_motor" ctrlrange="-5.0 5.0"/>
    <motor name="x5_joint6_ctrl" joint="x5_joint6" class="arx5_motor" ctrlrange="-5.0 5.0"/>

  </actuator>

</mujoco>